Workbook
Name AMB: #REF!
Name AMB: #REF!
Name clear: #REF!
Name clear: #REF!
Name CoEq: [1]Control_Panel!$E$12
Name cost: #REF!
Name cost: #REF!
Name costlist: [2]Data!$I$2:$I$5
Name count: #REF!
Name count: #REF!
Name countlist: [2]Data!$H$2:$H$6
Name coverage: #REF!
Name coverage: #REF!
Name coveragelist: [2]Data!$AE$2:$AE$7
Name Date: [1]Control_Panel!$E$11
Name i: #REF!
Name impact: #REF!
Name impact: #REF!
Name Loss: #REF!
Name Loss: #REF!
Name Ltg: [1]Control_Panel!$E$16
Name P_base: [1]Control_Panel!$F$20
Name P_down: [1]Control_Panel!$F$22
Name P_up: [1]Control_Panel!$F$21
Name Peril: #REF!
Name Peril: #REF!
Name Project_name: [1]Control_Panel!$E$10
Name RANGE: '[3]First Loss Scale'!$C$5:$AG$5
Name Scenario: [1]Control_Panel!$E$19
Name TargetSolvency: [1]Control_Panel!$E$13
Name Tax: [1]Control_Panel!$E$15
Name Territory: #REF!
Name Territory: #REF!
Name test: #REF!
Name test: #REF!
Name v: #REF!
Name VPs: '[4]Vulnerability Profiling'!$DE$3:$DN$10
Name Yield: [1]Control_Panel!$E$14

Sheet Infos
A1: SIM' Assurances
C4: Produit Agricole Indiciel
B6: Produit | C6: Description du produit
B7: Tarification | C7: Tarification du produit
B8: Commissions | C8: Frais de gestion, commissions de distribution, et taxes
B10: (1) | C10: CIMA H
B11: (2) | C11: Modele et donnees historiques 2001 - 2024: Africa Risk View
B12: (3) | C12: Demographie & Departements - CI

Sheet Produit
A1: SIM' Assurances
C5: Produit Agricole Indiciel
C7: Type | D7: Contrat Agricole Indiciel
C8: Garanties | D8: En cas de forte sécheresse - moins de 75% de la valeur de référence de l'indice WRSI: indemnisation forfaitaire de 100.000 fcfa
D9: En cas de moyenne sécheresse - entre 76% et 85% de la valeur de référence de l'indice WRSI: indemnité forfaitaire de 50.000 fcfa
D10: En cas de faible sécheresse - entre 86% et 95% de la valeur de référence de l'indice WRSI: indemnité forfaitaire de 10.000 fcfa
D11: En cas de décès du producteur : paiement du capital de 100.000 fcfa à la famille du producteur.
C12: Définitions | D12: WRSI: indice de sécheresse défini par la FAO et publié par ARC (l'organisme assureur de l'Union Africaine) pour chaque région de la Côte d'Ivoire; la valeur de référence est la médiane des valeurs des cinq dernières années de l'indice pour une localité donnée.
D13: Région: région d'activités de l'Assuré
C14: Données | D14: Les données proviennent du satelitte CHIRP
C15: Spéculations | D15: Maïs, Mil, Sorgho
C16: Type de prime | D16: Prime unique
C17: Période de cotisation | D17: Paiement des primes entre le XXXXXX et le XXXXXX
C18: Date d'effet | D18: Date de paiement de l'intégralité de la prime. Remboursement de la prime sans prise d'effet des garanties en cas de non paiement de la cotisation au XXXXXXX
C19: Date d'expiration | D19: Paiement automatique a l'Assuré du montant garanti selon le niveau de l'indice le 31 Décembre
C20: Forme de la police | D20: A la souscription de la police, l'Assureur transmet à l'Assuré: - une carte d'assurance (conditions générales et conditions particulières) - un certificat d'adhésion par SMS ou mail (numéro d'Assuré, nom, prénom, date d'expiration)

Sheet Tarification
A1: SIM' Assurances
C5: Tarification
C7: Garanties | G7: % indemnisation | H7: % baisse de l'indice
C8: 1. Faible secheresse | D8: =+G8*D10 -> 50000 | E8: FCFA | F8: a | G8: 0.2 | H8: 0.95
C9: 2. Moyenne secheresse | D9: =G9*D10 -> 125000 | E9: FCFA | F9: b | G9: 0.5 | H9: 0.85
C10: 3. Forte secheresse | D10: 250000 | E10: FCFA | F10: c | G10: 1 | H10: 0.75
C11: 4. Décès de l'agriculteur | D11: 250000 | E11: FCFA | F11: d
C12: Prime de risque annuelle secheresse | D12: =+'(2) ARV Model'!$AQ$3 -> 9819.4847 | F12: e = p x a + q x (b - a) + r x (c - b)
C13: Prime de risque annuelle deces | D13: =D31*D11 -> 1317.8107 | F13: f = s x c
C14: Chargement pour distribution | D14: 0.22 | F14: g
C15: Marge et frais de l'assureur | D15: 0.4 | F15: h
C16: Prime commerciale annuelle HT - Secheresse | D16: =D12/(1-D14-D15) -> 25840.749 | F16: i = e / ( 1 - g - h)
C17: Prime commerciale annuelle HT - DC | D17: =D13/(1-D14-D15) -> 3467.9228 | F17: j = f / ( 1 - g - h)
C18: Taxes - Secheresse | D18: =+Commissions!D14 -> 0.0725 | F18: k
C19: Prime commerciale annuelle TTC | D19: =D16*(1+D18)+D17 -> 31182.126 | F19: l = i x ( 1 + k ) + j
C20: Taux de prime | D20: =SUM(D17,D16)/(D10+D11) -> 0.058617344 | F20: m = ( i + j ) / c
C21: Taux de sinistres | D21: =(D12+D13)/(D10+D11) -> 0.022274591 | F21: n = ( e + f ) / c
C22: Ratio S/P | D22: =D21/D20 -> 0.38 | F22: o = n / m
C23: Vente | D23: =(ROUND(D19/1000,1)+0.1)*1000 -> 31300
C26: Frequence
C28: --- faible secheresse | D28: =+'(2) ARV Model'!$AU$3 -> 0.13071634 | F28: p ---> Modele ARV
C29: --- moyenne secheresse | D29: =+'(2) ARV Model'!$AV$3 -> 0.036576865 | F29: q ---> Modele ARV
C30: --- forte secheresse | D30: =+'(2) ARV Model'!$AW$3 -> 0.0043232243 | F30: r ---> Modele ARV
C31: --- DC | D31: =+'(1) CIMA H'!G58 -> 0.0052712427 | F31: s ---> TD CIMA 45 ans
C32: Frequence totale secheresse | D32: =(D28*D8+D29*(D9-D8)+D30*(D10-D9))/D10 -> 0.039277939 | F32: t = (p x a + q x ( b - a ) + r x ( c - b ) ) / c
C33: Frequence totale Deces | D33: =D31 -> 0.0052712427 | F33: u = s

Sheet Commissions
A1: SIM' Assurances
C5: Commissions & Frais
E7: Trimestre 1 | F7: Trimestre 2 | G7: Trimestre 3 | H7: Trimestre 4
C8: Commission Distribution | D8: =SUM(E8:H8)/4 -> 0.27 | E8: 0.27 | F8: =+E8 -> 0.27 | G8: =+F8 -> 0.27 | H8: =+G8 -> 0.27
C10: Chargement pour distribution | D10: =SUM(E10:H10)/4 -> 0.27 | E10: =E9+E8 -> 0.27 | F10: =F9+F8 -> 0.27 | G10: =G9+G8 -> 0.27 | H10: =H9+H8 -> 0.27
C12: Reprises de commissions | D12: NA
C14: Taxes | D14: 0.0725
D16: Source : | E16: https://www.dgi.gouv.ci/assets/documents/LE%20SYSTEME%20FISCAL%20IVOIRIEN.pdf

Sheet (1) CIMA H
D9: Table de mortalité CIMA H
E12: Age | F12: Lx (CIMA H) | G12: qx (CIMA H) | H12: dx (CIMA H)
E13: 0 | F13: 1000000 | G13: =IF(F13=0,1,H13/F13) -> 0.0053677459 | H13: =+F13-F14 -> 5367.7459
E14: 1 | F14: 994632.25 | G14: =IF(F14=0,1,H14/F14) -> 0.00073000062 | H14: =+F14-F15 -> 726.08216
E15: 2 | F15: 993906.17 | G15: =IF(F15=0,1,H15/F15) -> 0.00055885073 | H15: =+F15-F16 -> 555.44519
E16: 3 | F16: 993350.73 | G16: =IF(F16=0,1,H16/F16) -> 0.00047618671 | H16: =+F16-F17 -> 473.02041
E17: 4 | F17: 992877.71 | G17: =IF(F17=0,1,H17/F17) -> 0.00040704388 | H17: =+F17-F18 -> 404.1448
E18: 5 | F18: 992473.56 | G18: =IF(F18=0,1,H18/F18) -> 0.00037124919 | H18: =+F18-F19 -> 368.455
E19: 6 | F19: 992105.11 | G19: =IF(F19=0,1,H19/F19) -> 0.0003344483 | H19: =+F19-F20 -> 331.80786
E20: 7 | F20: 991773.3 | G20: =IF(F20=0,1,H20/F20) -> 0.00031563494 | H20: =+F20-F21 -> 313.03831
E21: 8 | F21: 991460.26 | G21: =IF(F21=0,1,H21/F21) -> 0.00031566727 | H21: =+F21-F22 -> 312.97155
E22: 9 | F22: 991147.29 | G22: =IF(F22=0,1,H22/F22) -> 0.00029652722 | H22: =+F22-F23 -> 293.90215
E23: 10 | F23: 990853.39 | G23: =IF(F23=0,1,H23/F23) -> 0.00031572945 | H23: =+F23-F24 -> 312.84159
E24: 11 | F24: 990540.55 | G24: =IF(F24=0,1,H24/F24) -> 0.00031576179 | H24: =+F24-F25 -> 312.77486
... E123: 110 | F123: 0 | G123: =IF(F123=0,1,H123/F123) -> 1 | H123: =+F123-F124 -> 0

Sheet (2) ARV Model
B1: SIM' Assurances
G2: Source population agricole | H2: https://agriculture.gouv.fr/cote-divoire-contexte-agricole-et-relations-internationales#:~:text=La%20population%20ivoirienne%20se%20partage,deux%20tiers%20de%20la%20population. | AU2: Faible | AV2: Moy | AW2: Forte
G3: Tx population agricole | H3: 0.46 | AQ3: =SUMPRODUCT(AQ583:AQ859, $G$8:$G$284)/SUM($G$8:$G$284) -> 9819.4847 | AU3: =SUMPRODUCT(AS293:AS569, $H$8:$H$284)/SUM($H$8:$H$284) -> 0.13071634 | AV3: =SUMPRODUCT(AT293:AT569, $H$8:$H$284)/SUM($H$8:$H$284) -> 0.036576865 | AW3: =SUMPRODUCT(AU293:AU569, $H$8:$H$284)/SUM($H$8:$H$284) -> 0.0043232243
I5: Triggers | Q5: WRSI - Valeurs observées 2001-2020
I6: Faible | J6: Moyen | K6: Forte | R6: 3 | S6: 4 | T6: 5 | U6: 6 | V6: 7 | W6: 8 | X6: 9 | Y6: 10 | Z6: 11 | AA6: 12 | AB6: 13 | AC6: 14 | AD6: 15 | AE6: 16 | AF6: 17 | AG6: 18 | AH6: 19 | AI6: 20 | AJ6: 21 | AK6: 22 | AL6: 23 | AM6: 24 | AN6: 25
C7: Country | D7: Region | E7: District | F7: Sous prefectures | G7: Population Totale | H7: Population agricole | I7: 1er déclenchement | J7: 2e déclenchement | K7: 3e déclenchement | N7: Region | O7: District | P7: Sous prefectures | Q7: 2001 | R7: 2002 | S7: 2003 | T7: 2004 | U7: 2005 | V7: 2006 | W7: 2007 | X7: 2008 | Y7: 2009 | Z7: 2010 | AA7: 2011 | AB7: 2012 | AC7: 2013 | AD7: 2014 | AE7: 2015 | AF7: 2016 | AG7: 2017 | AH7: 2018 | AI7: 2019 | AJ7: 2020 | AK7: 2021 | AL7: 2022 | AM7: 2023 | AN7: 2024
C8: COTE D'IVOIRE | D8: Centre | E8: DIMBOKRO | F8: Abigui | G8: =VLOOKUP(F8,'(3) Demographie & Departements'!$G$8:$J$526,4,0) -> 8665.3727 | H8: =$H$3*G8 -> 3986.0714 | I8: =Tarification!$H$8 -> 0.95 | J8: =Tarification!$H$9 -> 0.85 | K8: =Tarification!$H$10 -> 0.75 | N8: Centre | O8: DIMBOKRO | P8: Abigui | Q8: 100 | R8: 100 | S8: 100 | T8: 100 | U8: 100 | V8: 100 | W8: 100 | X8: 100 | Y8: 100 | Z8: 100 | AA8: 100 | AB8: 100 | AC8: 100 | AD8: 100 | AE8: 100 | AF8: 100 | AG8: 100 | AH8: 100 | AI8: 100 | AJ8: 100 | AK8: 100 | AL8: 100 | AM8: 100 | AN8: 100
C9: COTE D'IVOIRE | D9: Centre | E9: OUELLE | F9: Akpassanou | G9: =VLOOKUP(F9,'(3) Demographie & Departements'!$G$8:$J$526,4,0) -> 5693.1684 | H9: =$H$3*G9 -> 2618.8575 | I9: =I8 -> 0.95 | J9: =J8 -> 0.85 | K9: =K8 -> 0.75 | N9: Centre | O9: OUELLE | P9: Akpassanou | Q9: 100 | R9: 99.70904 | S9: 100 | T9: 99.816795 | U9: 99.699901 | V9: 100 | W9: 90.869026 | X9: 100 | Y9: 98.890445 | Z9: 99.502109 | AA9: 95.076262 | AB9: 100 | AC9: 100 | AD9: 100 | AE9: 85.752635 | AF9: 99.849028 | AG9: 100 | AH9: 99.560979 | AI9: 99.762925 | AJ9: 100 | AK9: 99.530486 | AL9: 100 | AM9: 100 | AN9: 98.055896
C10: COTE D'IVOIRE | D10: Centre | E10: TANDA | F10: Amanvi | G10: =VLOOKUP(F10,'(3) Demographie & Departements'!$G$8:$J$526,4,0) -> 10140.78 | H10: =$H$3*G10 -> 4664.7588 | I10: =I9 -> 0.95 | J10: =J9 -> 0.85 | K10: =K9 -> 0.75 | N10: Centre | O10: TANDA | P10: Amanvi | Q10: 100 | R10: 100 | S10: 100 | T10: 87.264303 | U10: 92.57711 | V10: 100 | W10: 95.249777 | X10: 100 | Y10: 100 | Z10: 100 | AA10: 100 | AB10: 100 | AC10: 90.566277 | AD10: 100 | AE10: 76.92464 | AF10: 93.993674 | AG10: 100 | AH10: 99.517981 | AI10: 100 | AJ10: 100 | AK10: 99.653128 | AL10: 100 | AM10: 100 | AN10: 99.978249
C11: COTE D'IVOIRE | D11: Centre | E11: OUELLE | F11: Ananda | G11: =VLOOKUP(F11,'(3) Demographie & Departements'!$G$8:$J$526,4,0) -> 13166.288 | H11: =$H$3*G11 -> 6056.4923 | I11: =I10 -> 0.95 | J11: =J10 -> 0.85 | K11: =K10 -> 0.75 | N11: Centre | O11: OUELLE | P11: Ananda | Q11: 100 | R11: 100 | S11: 100 | T11: 99.956049 | U11: 100 | V11: 100 | W11: 92.364238 | X11: 100 | Y11: 100 | Z11: 99.925044 | AA11: 98.874753 | AB11: 100 | AC11: 100 | AD11: 100 | AE11: 89.348607 | AF11: 100 | AG11: 100 | AH11: 100 | AI11: 100 | AJ11: 100 | AK11: 100 | AL11: 100 | AM11: 100 | AN11: 99.938185
C12: COTE D'IVOIRE | D12: Centre | E12: BONGOUANOU | F12: Ande | G12: =VLOOKUP(F12,'(3) Demographie & Departements'!$G$8:$J$526,4,0) -> 58286.682 | H12: =$H$3*G12 -> 26811.873 | I12: =I11 -> 0.95 | J12: =J11 -> 0.85 | K12: =K11 -> 0.75 | N12: Centre | O12: BONGOUANOU | P12: Ande | Q12: 100 | R12: 100 | S12: 100 | T12: 100 | U12: 100 | V12: 100 | W12: 100 | X12: 100 | Y12: 100 | Z12: 100 | AA12: 100 | AB12: 100 | AC12: 100 | AD12: 100 | AE12: 100 | AF12: 100 | AG12: 100 | AH12: 100 | AI12: 100 | AJ12: 100 | AK12: 100 | AL12: 100 | AM12: 100 | AN12: 99.222583
C13: COTE D'IVOIRE | D13: Centre | E13: BEOUMI | F13: Ando-Kekrenou | G13: =VLOOKUP(F13,'(3) Demographie & Departements'!$G$8:$J$526,4,0) -> 16825.632 | H13: =$H$3*G13 -> 7739.7909 | I13: =I12 -> 0.95 | J13: =J12 -> 0.85 | K13: =K12 -> 0.75 | N13: Centre | O13: BEOUMI | P13: Ando-Kekrenou | Q13: 100 | R13: 100 | S13: 99.817994 | T13: 100 | U13: 98.756442 | V13: 100 | W13: 92.058464 | X13: 100 | Y13: 98.929726 | Z13: 98.559833 | AA13: 97.673561 | AB13: 100 | AC13: 100 | AD13: 100 | AE13: 89.135152 | AF13: 99.152723 | AG13: 100 | AH13: 99.814677 | AI13: 96.493868 | AJ13: 99.141929 | AK13: 99.576943 | AL13: 99.686531 | AM13: 100 | AN13: 92.82755
C14: COTE D'IVOIRE | D14: Centre | E14: TOUMODI | F14: Angoda | G14: =VLOOKUP(F14,'(3) Demographie & Departements'!$G$8:$J$526,4,0) -> 11818.835 | H14: =$H$3*G14 -> 5436.6639 | I14: =I13 -> 0.95 | J14: =J13 -> 0.85 | K14: =K13 -> 0.75 | N14: Centre | O14: TOUMODI | P14: Angoda | Q14: 100 | R14: 100 | S14: 100 | T14: 100 | U14: 100 | V14: 100 | W14: 100 | X14: 100 | Y14: 100 | Z14: 100 | AA14: 100 | AB14: 100 | AC14: 100 | AD14: 100 | AE14: 100 | AF14: 100 | AG14: 100 | AH14: 100 | AI14: 100 | AJ14: 100 | AK14: 100 | AL14: 100 | AM14: 100 | AN14: 100
C15: COTE D'IVOIRE | D15: Centre | E15: PRIKRO | F15: Anianou | G15: =VLOOKUP(F15,'(3) Demographie & Departements'!$G$8:$J$526,4,0) -> 7956.2094 | H15: =$H$3*G15 -> 3659.8563 | I15: =I14 -> 0.95 | J15: =J14 -> 0.85 | K15: =K14 -> 0.75 | N15: Centre | O15: PRIKRO | P15: Anianou | Q15: 100 | R15: 100 | S15: 100 | T15: 91.118567 | U15: 91.167471 | V15: 100 | W15: 93.354219 | X15: 100 | Y15: 99.987177 | Z15: 100 | AA15: 100 | AB15: 100 | AC15: 100 | AD15: 100 | AE15: 86.299556 | AF15: 88.682365 | AG15: 99.597557 | AH15: 98.516627 | AI15: 99.31649 | AJ15: 100 | AK15: 98.911061 | AL15: 98.347001 | AM15: 100 | AN15: 85.203439
C16: COTE D'IVOIRE | D16: Centre | E16: M'BATTO | F16: Anoumaba | G16: =VLOOKUP(F16,'(3) Demographie & Departements'!$G$8:$J$526,4,0) -> 22571.867 | H16: =$H$3*G16 -> 10383.059 | I16: =I15 -> 0.95 | J16: =J15 -> 0.85 | K16: =K15 -> 0.75 | N16: Centre | O16: M'BATTO | P16: Anoumaba | Q16: 100 | R16: 100 | S16: 100 | T16: 100 | U16: 100 | V16: 100 | W16: 100 | X16: 100 | Y16: 100 | Z16: 100 | AA16: 100 | AB16: 100 | AC16: 100 | AD16: 100 | AE16: 100 | AF16: 100 | AG16: 100 | AH16: 100 | AI16: 100 | AJ16: 100 | AK16: 100 | AL16: 100 | AM16: 100 | AN16: 100
C17: COTE D'IVOIRE | D17: Centre | E17: BONDOUKOU | F17: Appimadoum | G17: =VLOOKUP(F17,'(3) Demographie & Departements'!$G$8:$J$526,4,0) -> 9919.5338 | H17: =$H$3*G17 -> 4562.9855 | I17: =I16 -> 0.95 | J17: =J16 -> 0.85 | K17: =K16 -> 0.75 | N17: Centre | O17: BONDOUKOU | P17: Appimadoum | Q17: 100 | R17: 100 | S17: 100 | T17: 92.135986 | U17: 100 | V17: 100 | W17: 100 | X17: 100 | Y17: 100 | Z17: 100 | AA17: 100 | AB17: 100 | AC17: 97.575032 | AD17: 100 | AE17: 90.180961 | AF17: 100 | AG17: 100 | AH17: 100 | AI17: 100 | AJ17: 100 | AK17: 100 | AL17: 100 | AM17: 100 | AN17: 100
C18: COTE D'IVOIRE | D18: Centre | E18: ARRAH | F18: Arrah | G18: =VLOOKUP(F18,'(3) Demographie & Departements'!$G$8:$J$526,4,0) -> 45625.37 | H18: =$H$3*G18 -> 20987.67 | I18: =I17 -> 0.95 | J18: =J17 -> 0.85 | K18: =K17 -> 0.75 | N18: Centre | O18: ARRAH | P18: Arrah | Q18: 100 | R18: 100 | S18: 100 | T18: 100 | U18: 100 | V18: 100 | W18: 100 | X18: 100 | Y18: 100 | Z18: 100 | AA18: 100 | AB18: 100 | AC18: 100 | AD18: 100 | AE18: 100 | AF18: 99.964311 | AG18: 100 | AH18: 100 | AI18: 100 | AJ18: 100 | AK18: 100 | AL18: 100 | AM18: 100 | AN18: 96.026325
C19: COTE D'IVOIRE | D19: Centre | E19: M'BATTO | F19: Assahara | G19: =VLOOKUP(F19,'(3) Demographie & Departements'!$G$8:$J$526,4,0) -> 11495.068 | H19: =$H$3*G19 -> 5287.7311 | I19: =I18 -> 0.95 | J19: =J18 -> 0.85 | K19: =K18 -> 0.75 | N19: Centre | O19: M'BATTO | P19: Assahara | Q19: 100 | R19: 100 | S19: 100 | T19: 100 | U19: 100 | V19: 100 | W19: 100 | X19: 100 | Y19: 100 | Z19: 100 | AA19: 100 | AB19: 100 | AC19: 100 | AD19: 100 | AE19: 100 | AF19: 100 | AG19: 100 | AH19: 100 | AI19: 100 | AJ19: 100 | AK19: 100 | AL19: 100 | AM19: 100 | AN19: 100
C20: COTE D'IVOIRE | D20: Centre | E20: BONGOUANOU | F20: Assie-Koumassi | G20: =VLOOKUP(F20,'(3) Demographie & Departements'!$G$8:$J$526,4,0) -> 21961.698 | H20: =$H$3*G20 -> 10102.381 | I20: =I19 -> 0.95 | J20: =J19 -> 0.85 | K20: =K19 -> 0.75 | N20: Centre | O20: BONGOUANOU | P20: Assie-Koumassi | Q20: 100 | R20: 100 | S20: 100 | T20: 100 | U20: 100 | V20: 100 | W20: 99.852603 | X20: 100 | Y20: 100 | Z20: 100 | AA20: 100 | AB20: 100 | AC20: 100 | AD20: 100 | AE20: 99.49304 | AF20: 100 | AG20: 100 | AH20: 100 | AI20: 100 | AJ20: 100 | AK20: 100 | AL20: 100 | AM20: 100 | AN20: 98.725415
... C242: COTE D'IVOIRE | D242: Nord | E242: TENGRELA | F242: Papara | G242: =VLOOKUP(F242,'(3) Demographie & Departements'!$G$8:$J$526,4,0) -> 13448.441 | H242: =$H$3*G242 -> 6186.283 | I242: =I241 -> 0.95 | J242: =J241 -> 0.85 | K242: =K241 -> 0.75 | N242: Nord | O242: TENGRELA | P242: Papara | Q242: 100 | R242: 100 | S242: 100 | T242: 92.86841 | U242: 100 | V242: 100 | W242: 100 | X242: 100 | Y242: 100 | Z242: 100 | AA242: 100 | AB242: 100 | AC242: 100 | AD242: 95.190813 | AE242: 99.523082 | AF242: 99.689782 | AG242: 100 | AH242: 100 | AI242: 99.746752 | AJ242: 97.430079 | AK242: 100 | AL242: 100 | AM242: 100 | AN242: 100
C243: COTE D'IVOIRE | D243: Nord | E243: 1 | F243: Parc National de Bouna | G243: 10000 | H243: =$H$3*G243 -> 4600 | I243: =I242 -> 0.95 | J243: =J242 -> 0.85 | K243: =K242 -> 0.75 | N243: Nord | O243: 1 | P243: Parc National de Bouna | Q243: 91.333459 | R243: 99.700933 | S243: 92.800784 | T243: 90.001411 | U243: 91.620959 | V243: 98.327544 | W243: 90.8785 | X243: 99.999562 | Y243: 98.784294 | Z243: 96.172963 | AA243: 99.959454 | AB243: 99.453858 | AC243: 84.360097 | AD243: 86.939893 | AE243: 90.331896 | AF243: 94.283878 | AG243: 90.735154 | AH243: 96.107808 | AI243: 98.820811 | AJ243: 87.669908 | AK243: 99.994716 | AL243: 98.986913 | AM243: 99.648759 | AN243: 82.872726
C244: COTE D'IVOIRE | D244: Nord | E244: SINEMATIALI | F244: Sediogo | G244: =VLOOKUP(F244,'(3) Demographie & Departements'!$G$8:$J$526,4,0) -> 6599.7005 | H244: =$H$3*G244 -> 3035.8622 | I244: =I243 -> 0.95 | J244: =J243 -> 0.85 | K244: =K243 -> 0.75 | N244: Nord | O244: SINEMATIALI | P244: Sediogo | Q244: 100 | R244: 100 | S244: 100 | T244: 99.362876 | U244: 100 | V244: 100 | W244: 100 | X244: 100 | Y244: 100 | Z244: 100 | AA244: 100 | AB244: 100 | AC244: 100 | AD244: 89.873846 | AE244: 100 | AF244: 99.306361 | AG244: 100 | AH244: 100 | AI244: 97.825246 | AJ244: 92.482438 | AK244: 100 | AL244: 100 | AM244: 100 | AN244: 100
C245: COTE D'IVOIRE | D245: Nord | E245: SEGUELA | F245: Seguela | G245: =VLOOKUP(F245,'(3) Demographie & Departements'!$G$8:$J$526,4,0) -> 103979.63 | H245: =$H$3*G245 -> 47830.632 | I245: =I244 -> 0.95 | J245: =J244 -> 0.85 | K245: =K244 -> 0.75 | N245: Nord | O245: SEGUELA | P245: Seguela | Q245: 89.209121 | R245: 100 | S245: 100 | T245: 83.915639 | U245: 96.028324 | V245: 99.675341 | W245: 87.330561 | X245: 100 | Y245: 98.402409 | Z245: 93.285717 | AA245: 87.391118 | AB245: 99.587679 | AC245: 95.947839 | AD245: 86.593274 | AE245: 88.588476 | AF245: 76.752653 | AG245: 90.645862 | AH245: 99.734677 | AI245: 94.227843 | AJ245: 87.374 | AK245: 100 | AL245: 96.100991 | AM245: 100 | AN245: 90.651856
C246: COTE D'IVOIRE | D246: Nord | E246: SEGUELON | F246: Seguelon | G246: =VLOOKUP(F246,'(3) Demographie & Departements'!$G$8:$J$526,4,0) -> 21213.267 | H246: =$H$3*G246 -> 9758.1027 | I246: =I245 -> 0.95 | J246: =J245 -> 0.85 | K246: =K245 -> 0.75 | N246: Nord | O246: SEGUELON | P246: Seguelon | Q246: 100 | R246: 100 | S246: 100 | T246: 100 | U246: 100 | V246: 100 | W246: 100 | X246: 100 | Y246: 100 | Z246: 100 | AA246: 100 | AB246: 100 | AC246: 100 | AD246: 100 | AE246: 99.972608 | AF246: 100 | AG246: 100 | AH246: 100 | AI246: 100 | AJ246: 100 | AK246: 100 | AL246: 100 | AM246: 100 | AN246: 100
C247: COTE D'IVOIRE | D247: Nord | E247: OUANINOU | F247: Saboudougou | G247: =VLOOKUP(F247,'(3) Demographie & Departements'!$G$8:$J$526,4,0) -> 5225.2745 | H247: =$H$3*G247 -> 2403.6263 | I247: =I246 -> 0.95 | J247: =J246 -> 0.85 | K247: =K246 -> 0.75 | N247: Nord | O247: OUANINOU | P247: Saboudougou | Q247: 100 | R247: 100 | S247: 100 | T247: 100 | U247: 100 | V247: 100 | W247: 100 | X247: 100 | Y247: 100 | Z247: 100 | AA247: 100 | AB247: 100 | AC247: 100 | AD247: 100 | AE247: 100 | AF247: 100 | AG247: 100 | AH247: 100 | AI247: 100 | AJ247: 100 | AK247: 100 | AL247: 100 | AM247: 100 | AN247: 100
C248: COTE D'IVOIRE | D248: Nord | E248: GBELEBAN | F248: Samango | G248: =VLOOKUP(F248,'(3) Demographie & Departements'!$G$8:$J$526,4,0) -> 17218.821 | H248: =$H$3*G248 -> 7920.6577 | I248: =I247 -> 0.95 | J248: =J247 -> 0.85 | K248: =K247 -> 0.75 | N248: Nord | O248: GBELEBAN | P248: Samango | Q248: 100 | R248: 100 | S248: 100 | T248: 100 | U248: 100 | V248: 100 | W248: 100 | X248: 100 | Y248: 100 | Z248: 100 | AA248: 100 | AB248: 100 | AC248: 100 | AD248: 100 | AE248: 100 | AF248: 100 | AG248: 100 | AH248: 100 | AI248: 100 | AJ248: 100 | AK248: 100 | AL248: 100 | AM248: 100 | AN248: 100
C249: COTE D'IVOIRE | D249: Nord | E249: SAMATIGUILA | F249: Samatiguila | G249: =VLOOKUP(F249,'(3) Demographie & Departements'!$G$8:$J$526,4,0) -> 7777.0846 | H249: =$H$3*G249 -> 3577.4589 | I249: =I248 -> 0.95 | J249: =J248 -> 0.85 | K249: =K248 -> 0.75 | N249: Nord | O249: SAMATIGUILA | P249: Samatiguila | Q249: 100 | R249: 100 | S249: 100 | T249: 100 | U249: 100 | V249: 100 | W249: 100 | X249: 100 | Y249: 100 | Z249: 100 | AA249: 100 | AB249: 100 | AC249: 100 | AD249: 100 | AE249: 100 | AF249: 100 | AG249: 100 | AH249: 100 | AI249: 100 | AJ249: 100 | AK249: 100 | AL249: 100 | AM249: 100 | AN249: 100
C250: COTE D'IVOIRE | D250: Centre | E250: SANDEGUE | F250: Sandegue | G250: =VLOOKUP(F250,'(3) Demographie & Departements'!$G$8:$J$526,4,0) -> 26917.944 | H250: =$H$3*G250 -> 12382.254 | I250: =I249 -> 0.95 | J250: =J249 -> 0.85 | K250: =K249 -> 0.75 | N250: Centre | O250: SANDEGUE | P250: Sandegue | Q250: 79.004428 | R250: 99.699542 | S250: 84.799858 | T250: 71.390933 | U250: 70.928668 | V250: 93.094512 | W250: 81.830857 | X250: 100 | Y250: 84.451566 | Z250: 100 | AA250: 100 | AB250: 100 | AC250: 79.092851 | AD250: 75.526015 | AE250: 70.354035 | AF250: 66.856554 | AG250: 93.700516 | AH250: 73.67492 | AI250: 97.43368 | AJ250: 82.720459 | AK250: 99.634895 | AL250: 93.948774 | AM250: 100 | AN250: 74.76458
C251: COTE D'IVOIRE | D251: Nord | E251: BIANKOUMA | F251: SANTA-BIANKOUMA | G251: =VLOOKUP(F251,'(3) Demographie & Departements'!$G$8:$J$526,4,0) -> 51818.758 | H251: =$H$3*G251 -> 23836.629 | I251: =I250 -> 0.95 | J251: =J250 -> 0.85 | K251: =K250 -> 0.75 | N251: Nord | O251: BIANKOUMA | P251: SANTA-BIANKOUMA | Q251: 100 | R251: 100 | S251: 100 | T251: 100 | U251: 100 | V251: 100 | W251: 100 | X251: 100 | Y251: 100 | Z251: 100 | AA251: 100 | AB251: 100 | AC251: 100 | AD251: 100 | AE251: 100 | AF251: 100 | AG251: 100 | AH251: 100 | AI251: 100 | AJ251: 100 | AK251: 100 | AL251: 100 | AM251: 100 | AN251: 100
C252: COTE D'IVOIRE | D252: Nord | E252: MANKONO | F252: Sarhala | G252: =VLOOKUP(F252,'(3) Demographie & Departements'!$G$8:$J$526,4,0) -> 42450.425 | H252: =$H$3*G252 -> 19527.196 | I252: =I251 -> 0.95 | J252: =J251 -> 0.85 | K252: =K251 -> 0.75 | N252: Nord | O252: MANKONO | P252: Sarhala | Q252: 90.272978 | R252: 99.841572 | S252: 80.554481 | T252: 75.701859 | U252: 90.218932 | V252: 88.648751 | W252: 80.882222 | X252: 99.945145 | Y252: 89.67926 | Z252: 71.435811 | AA252: 88.875573 | AB252: 100 | AC252: 99.371248 | AD252: 79.102726 | AE252: 74.166182 | AF252: 82.593397 | AG252: 82.279744 | AH252: 90.84944 | AI252: 84.598807 | AJ252: 86.813691 | AK252: 88.325483 | AL252: 99.708998 | AM252: 97.10997 | AN252: 85.490111
C253: COTE D'IVOIRE | D253: Nord | E253: DABAKALA | F253: Satama-Sokoro | G253: =VLOOKUP(F253,'(3) Demographie & Departements'!$G$8:$J$526,4,0) -> 26162.873 | H253: =$H$3*G253 -> 12034.922 | I253: =I252 -> 0.95 | J253: =J252 -> 0.85 | K253: =K252 -> 0.75 | N253: Nord | O253: DABAKALA | P253: Satama-Sokoro | Q253: 78.473866 | R253: 95.593037 | S253: 82.529412 | T253: 85.853236 | U253: 71.365731 | V253: 89.538597 | W253: 91.274767 | X253: 100 | Y253: 87.364989 | Z253: 90.829496 | AA253: 91.421124 | AB253: 91.780095 | AC253: 74.652271 | AD253: 72.245758 | AE253: 70.596851 | AF253: 65.272497 | AG253: 93.835114 | AH253: 93.92181 | AI253: 87.37377 | AJ253: 74.115436 | AK253: 100 | AL253: 99.478899 | AM253: 94.352173 | AN253: 81.820732
C254: COTE D'IVOIRE | D254: Nord | E254: DABAKALA | F254: Satama-Sokoura | G254: =VLOOKUP(F254,'(3) Demographie & Departements'!$G$8:$J$526,4,0) -> 13066.55 | H254: =$H$3*G254 -> 6010.6131 | I254: =I253 -> 0.95 | J254: =J253 -> 0.85 | K254: =K253 -> 0.75 | N254: Nord | O254: DABAKALA | P254: Satama-Sokoura | Q254: 75.382831 | R254: 93.214101 | S254: 81.118369 | T254: 92.19986 | U254: 70.230293 | V254: 90.276192 | W254: 88.948511 | X254: 100 | Y254: 87.93062 | Z254: 94.744696 | AA254: 92.094551 | AB254: 92.988773 | AC254: 72.382869 | AD254: 70.546689 | AE254: 71.371882 | AF254: 62.052121 | AG254: 95.72677 | AH254: 93.123289 | AI254: 82.994977 | AJ254: 69.927547 | AK254: 100 | AL254: 95.587951 | AM254: 92.239661 | AN254: 81.909809
C255: COTE D'IVOIRE | D255: Nord | E255: GBELEBAN | F255: Seydougou | G255: =VLOOKUP(F255,'(3) Demographie & Departements'!$G$8:$J$526,4,0) -> 7806.2264 | H255: =$H$3*G255 -> 3590.8641 | I255: =I254 -> 0.95 | J255: =J254 -> 0.85 | K255: =K254 -> 0.75 | N255: Nord | O255: GBELEBAN | P255: Seydougou | Q255: 100 | R255: 100 | S255: 100 | T255: 100 | U255: 100 | V255: 100 | W255: 100 | X255: 100 | Y255: 100 | Z255: 100 | AA255: 100 | AB255: 100 | AC255: 100 | AD255: 100 | AE255: 100 | AF255: 100 | AG255: 100 | AH255: 100 | AI255: 100 | AJ255: 100 | AK255: 100 | AL255: 100 | AM255: 100 | AN255: 100
... C284: COTE D'IVOIRE | D284: Nord | E284: BOUNA | F284: Youndouo | G284: =VLOOKUP(F284,'(3) Demographie & Departements'!$G$8:$J$526,4,0) -> 24825.647 | H284: =$H$3*G284 -> 11419.798 | I284: =I283 -> 0.95 | J284: =J283 -> 0.85 | K284: =K283 -> 0.75 | N284: Nord | O284: BOUNA | P284: Youndouo | Q284: 86.834677 | R284: 100 | S284: 87.944217 | T284: 92.080398 | U284: 95.604482 | V284: 95.811729 | W284: 93.639523 | X284: 100 | Y284: 100 | Z284: 98.540059 | AA284: 99.944237 | AB284: 99.857084 | AC284: 75.096378 | AD284: 91.69211 | AE284: 81.255202 | AF284: 92.601345 | AG284: 86.058812 | AH284: 85.759544 | AI284: 99.500967 | AJ284: 88.850773 | AK284: 100 | AL284: 99.384919 | AM284: 100 | AN284: 82.063109
M291: WRSI - deviations 2001-2020 | AS291: Frequences (Cumulatives) Secheresse: | BE291: Frequences (Specifiques) Secheresse:
N292: Region | O292: District | P292: Sous prefectures | Q292: 2001 | R292: 2002 | S292: 2003 | T292: 2004 | U292: 2005 | V292: 2006 | W292: 2007 | X292: 2008 | Y292: 2009 | Z292: 2010 | AA292: 2011 | AB292: 2012 | AC292: 2013 | AD292: 2014 | AE292: 2015 | AF292: 2016 | AG292: 2017 | AH292: 2018 | AI292: 2019 | AJ292: 2020 | AK292: 2021 | AL292: 2022 | AM292: 2023 | AN292: 2024 | AS292: >=Faible | AT292: >=Moyenne | AU292: >=Severe | AW292: Faible | AX292: Moyenne | AY292: Severe | BA292: Faible | BB292: Moyenne | BC292: Severe | BE292: Faible | BF292: Moyenne | BG292: Severe
N293: Centre | O293: DIMBOKRO | P293: Abigui | V293: =V8/MEDIAN(Q8:U8) -> 1 | W293: =W8/MEDIAN(R8:V8) -> 1 | X293: =X8/MEDIAN(S8:W8) -> 1 | Y293: =Y8/MEDIAN(T8:X8) -> 1 | Z293: =Z8/MEDIAN(U8:Y8) -> 1 | AA293: =AA8/MEDIAN(V8:Z8) -> 1 | AB293: =AB8/MEDIAN(W8:AA8) -> 1 | AC293: =AC8/MEDIAN(X8:AB8) -> 1 | ... AN293: =AN8/MEDIAN(AI8:AM8) -> 1 | AS293: {=SUMPRODUCT(($V293:$AN293<=$I8)*(1))/COUNT($V293:$AN293)} -> 0 | AT293: {=SUMPRODUCT(($V293:$AN293<=$J8)*(1))/COUNT($V293:$AN293)} -> 0 | AU293: {=SUMPRODUCT(($V293:$AN293<=$K8)*(1))/COUNT($V293:$AN293)} -> 0 | AW293: {=SUMPRODUCT(($V293:$AN293<=$I8)*(1))} -> 0 | AX293: {=SUMPRODUCT(($V293:$AN293<=$J8)*(1))} -> 0 | AY293: {=SUMPRODUCT(($V293:$AN293<=$K8)*(1))} -> 0 | BA293: =AW293-AX293 -> 0 | BB293: =AX293-AY293 -> 0 | BC293: =AY293 -> 0 | BE293: =BA293/COUNT($V293:$AN293) -> 0 | BF293: =BB293/COUNT($V293:$AN293) -> 0 | BG293: =BC293/COUNT($V293:$AN293) -> 0
N294: Centre | O294: OUELLE | P294: Akpassanou | V294: =V9/MEDIAN(Q9:U9) -> 1.0018354 | W294: =W9/MEDIAN(R9:V9) -> 0.91035808 | X294: =X9/MEDIAN(S9:W9) -> 1.0018354 | Y294: =Y9/MEDIAN(T9:X9) -> 0.9907195 | Z294: =Z9/MEDIAN(U9:Y9) -> 0.99801612 | AA294: =AA9/MEDIAN(V9:Z9) -> 0.95552007 | AB294: =AB9/MEDIAN(W9:AA9) -> 1.01122 | AC294: =AC9/MEDIAN(X9:AB9) -> 1.0050038 | ... AN294: =AN9/MEDIAN(AI9:AM9) -> 0.98055896 | AS294: {=SUMPRODUCT(($V294:$AN294<=$I9)*(1))/COUNT($V294:$AN294)} -> 0.10526316 | AT294: {=SUMPRODUCT(($V294:$AN294<=$J9)*(1))/COUNT($V294:$AN294)} -> 0 | AU294: {=SUMPRODUCT(($V294:$AN294<=$K9)*(1))/COUNT($V294:$AN294)} -> 0 | AW294: {=SUMPRODUCT(($V294:$AN294<=$I9)*(1))} -> 2 | AX294: {=SUMPRODUCT(($V294:$AN294<=$J9)*(1))} -> 0 | AY294: {=SUMPRODUCT(($V294:$AN294<=$K9)*(1))} -> 0 | BA294: =AW294-AX294 -> 2 | BB294: =AX294-AY294 -> 0 | BC294: =AY294 -> 0 | BE294: =BA294/COUNT($V294:$AN294) -> 0.10526316 | BF294: =BB294/COUNT($V294:$AN294) -> 0 | BG294: =BC294/COUNT($V294:$AN294) -> 0
N295: Centre | O295: TANDA | P295: Amanvi | V295: =V10/MEDIAN(Q10:U10) -> 1 | W295: =W10/MEDIAN(R10:V10) -> 0.95249777 | X295: =X10/MEDIAN(S10:W10) -> 1.0498712 | Y295: =Y10/MEDIAN(T10:X10) -> 1.0498712 | Z295: =Z10/MEDIAN(U10:Y10) -> 1 | AA295: =AA10/MEDIAN(V10:Z10) -> 1 | AB295: =AB10/MEDIAN(W10:AA10) -> 1 | AC295: =AC10/MEDIAN(X10:AB10) -> 0.90566277 | ... AN295: =AN10/MEDIAN(AI10:AM10) -> 0.99978249 | AS295: {=SUMPRODUCT(($V295:$AN295<=$I10)*(1))/COUNT($V295:$AN295)} -> 0.15789474 | AT295: {=SUMPRODUCT(($V295:$AN295<=$J10)*(1))/COUNT($V295:$AN295)} -> 0.052631579 | AU295: {=SUMPRODUCT(($V295:$AN295<=$K10)*(1))/COUNT($V295:$AN295)} -> 0 | AW295: {=SUMPRODUCT(($V295:$AN295<=$I10)*(1))} -> 3 | AX295: {=SUMPRODUCT(($V295:$AN295<=$J10)*(1))} -> 1 | AY295: {=SUMPRODUCT(($V295:$AN295<=$K10)*(1))} -> 0 | BA295: =AW295-AX295 -> 2 | BB295: =AX295-AY295 -> 1 | BC295: =AY295 -> 0 | BE295: =BA295/COUNT($V295:$AN295) -> 0.10526316 | BF295: =BB295/COUNT($V295:$AN295) -> 0.052631579 | BG295: =BC295/COUNT($V295:$AN295) -> 0
N296: Centre | O296: OUELLE | P296: Ananda | V296: =V11/MEDIAN(Q11:U11) -> 1 | W296: =W11/MEDIAN(R11:V11) -> 0.92364238 | X296: =X11/MEDIAN(S11:W11) -> 1 | Y296: =Y11/MEDIAN(T11:X11) -> 1 | Z296: =Z11/MEDIAN(U11:Y11) -> 0.99925044 | AA296: =AA11/MEDIAN(V11:Z11) -> 0.98874753 | AB296: =AB11/MEDIAN(W11:AA11) -> 1.0007501 | AC296: =AC11/MEDIAN(X11:AB11) -> 1 | ... AN296: =AN11/MEDIAN(AI11:AM11) -> 0.99938185 | AS296: {=SUMPRODUCT(($V296:$AN296<=$I11)*(1))/COUNT($V296:$AN296)} -> 0.10526316 | AT296: {=SUMPRODUCT(($V296:$AN296<=$J11)*(1))/COUNT($V296:$AN296)} -> 0 | AU296: {=SUMPRODUCT(($V296:$AN296<=$K11)*(1))/COUNT($V296:$AN296)} -> 0 | AW296: {=SUMPRODUCT(($V296:$AN296<=$I11)*(1))} -> 2 | AX296: {=SUMPRODUCT(($V296:$AN296<=$J11)*(1))} -> 0 | AY296: {=SUMPRODUCT(($V296:$AN296<=$K11)*(1))} -> 0 | BA296: =AW296-AX296 -> 2 | BB296: =AX296-AY296 -> 0 | BC296: =AY296 -> 0 | BE296: =BA296/COUNT($V296:$AN296) -> 0.10526316 | BF296: =BB296/COUNT($V296:$AN296) -> 0 | BG296: =BC296/COUNT($V296:$AN296) -> 0
...

Sheet (3) Demographie & Departements
A1: SIM' Assurances
C3: Source: INS
C4: Pop agricole | D4: ='(2) ARV Model'!H3 -> 0.46 | F4: https://agriculture.gouv.fr/cote-divoire-contexte-agricole-et-relations-internationales#:~:text=La%20population%20ivoirienne%20se%20partage,deux%20tiers%20de%20la%20population.
E7: N° | F7: DEPARTEMENT/REGION/DISTRICT | G7: SOUS-PREFECTURE | H7: HOMMES | I7: FEMMES | J7: TOTAL | K7: Population agri
E8: 1 | F8: ABIDJAN | G8: ABOBO | H8: 680421.62 | I8: 659661.11 | J8: 1340082.7 | K8: =ROUND($D$4*J8,0) -> 616438
E9: 2 | F9: ABIDJAN | G9: ADJAME | H9: 180917.19 | I9: 159974.42 | J9: 340891.61 | K9: =ROUND($D$4*J9,0) -> 156810
E10: 3 | F10: ABIDJAN | G10: ATTECOUBE | H10: 163988.65 | I10: 149146.36 | J10: 313135.01 | K10: =ROUND($D$4*J10,0) -> 144042
E11: 4 | F11: ABIDJAN | G11: COCODY | H11: 330016.05 | I11: 362566.46 | J11: 692582.51 | K11: =ROUND($D$4*J11,0) -> 318588
E12: 5 | F12: ABIDJAN | G12: KOUMASSI | H12: 209098.07 | I12: 203184.29 | J12: 412282.36 | K12: =ROUND($D$4*J12,0) -> 189650
E13: 6 | F13: ABIDJAN | G13: MARCORY | H13: 110457.91 | I13: 103603.14 | J13: 214061.05 | K13: =ROUND($D$4*J13,0) -> 98468
E14: 7 | F14: ABIDJAN | G14: PLATEAU | H14: 3634.9941 | I14: 3550.6776 | J14: 7185.6717 | K14: =ROUND($D$4*J14,0) -> 3305
E15: 8 | F15: ABIDJAN | G15: PORT-BOUET | H15: 321725.8 | I15: 297069.59 | J15: 618795.39 | K15: =ROUND($D$4*J15,0) -> 284646
E16: 9 | F16: ABIDJAN | G16: TREICHVILLE | H16: 55910.263 | I16: 50641.552 | J16: 106551.82 | K16: =ROUND($D$4*J16,0) -> 49014
E17: 10 | F17: ABIDJAN | G17: YOPOUGON | H17: 795443.02 | I17: 775621.97 | J17: 1571065 | K17: =ROUND($D$4*J17,0) -> 722690
E18: 11 | F18: ABIDJAN | G18: ANYAMA | H18: 200516.57 | I18: 189075.67 | J18: 389592.23 | K18: =ROUND($D$4*J18,0) -> 179212
E19: 12 | F19: ABIDJAN | G19: BINGERVILLE | H19: 101396.95 | I19: 103259.01 | J19: 204655.96 | K19: =ROUND($D$4*J19,0) -> 94142
... E526: 519 | F526: TEHINI | G526: TOUGBO | H526: 15716.215 | I526: 14865.89 | J526: 30582.105 | K526: =ROUND($D$4*J526,0) -> 14068
